Workbook

Sheet IKU 1A
A1: FAKULTAS : | M1: IKU 1A
A7: No | B7: Program Studi | C7: Tahun Kelulusan | D7: Jumlah Lulusan | E7: Jumlah Responden | F7: Jumlah lulusan yang berhasil mendapat pekerjaan | J7: Tempat Kerja | N7: Jumlah
F8: Masa Tunggu ≤ 6 Bulan | H8: Masa Tunggu > 6 s.d. 12 Bulan | J8: Swasta | K8: Nirlaba | L8: Institusi/ organisasi Multilateral | M8: Lembaga Pemerintah/BUMD/BUMN
F9: Besaran Gaji ≥ 1,2 Kali UMP | G9: Besaran Gaji < 1,2 UMP | H9: Besaran Gaji ≥ 1,2 Kali UMP | I9: Besaran Gaji < 1,2 UMP
A10: 1 | B10: Hukum | C10: 2024 | D10: 94 | E10: 93 | F10: 20 | G10: 1 | H10: 44 | I10: 4 | J10: 13 | K10: 23 | L10: 1 | M10: 4 | N10: =SUM(F10:I10) -> 69
A11: 2 | B11: Manajemen | C11: 2024 | D11: 108 | E11: 61 | F11: 8 | G11: 12 | H11: 1 | I11: 0 | J11: 12 | K11: 3 | L11: 0 | M11: 6 | N11: =SUM(F11:I11) -> 21
A12: 3 | B12: Ekonomi Pembangunan | C12: 2024 | D12: 111 | E12: 23 | F12: 6 | G12: 6 | H12: 0 | I12: 0 | J12: 4 | K12: 1 | L12: 0 | M12: 3 | N12: =SUM(F12:I12) -> 12
A13: 4 | B13: Akuntansi | C13: 2024 | D13: 69 | E13: 38 | F13: 3 | G13: 7 | H13: 1 | I13: 2 | J13: 7 | K13: 1 | L13: 0 | M13: 6 | N13: =SUM(F13:I13) -> 13
A14: 5 | B14: Agroteknologi | C14: 2024 | D14: 53 | E14: 27 | F14: 10 | G14: 7 | H14: 0 | I14: 5 | J14: 13 | K14: 1 | L14: 0 | M14: 4 | N14: =SUM(F14:I14) -> 22
A15: 6 | B15: Agribisnis | C15: 2024 | D15: 51 | E15: 51 | F15: 6 | G15: 13 | H15: 2 | I15: 15 | J15: 29 | K15: 2 | L15: 1 | M15: 4 | N15: =SUM(F15:I15) -> 36
A16: 7 | B16: Akuakultur | C16: 2024 | D16: 24 | E16: 16 | F16: 1 | G16: 2 | H16: 0 | I16: 0 | J16: 2 | K16: 0 | L16: 0 | M16: 1 | N16: =SUM(F16:I16) -> 3
A17: 8 | B17: Pendidikan Sejarah | C17: 2024 | D17: 62 | E17: 35 | F17: 8 | G17: 10 | H17: 7 | I17: 10 | J17: 5 | K17: - | L17: - | M17: 25 | N17: =SUM(F17:I17) -> 35
A18: 9 | B18: Pendidikan Biologi | C18: 2024 | D18: 72 | E18: 56 | F18: 2 | G18: 7 | H18: - | I18: - | J18: - | K18: 2 | L18: 2 | M18: 3 | N18: =SUM(F18:I18) -> 9
A19: 10 | B19: Pendidikan Bahasa Inggris | C19: 2024 | D19: 58 | E19: 30 | F19: 5 | G19: 15 | H19: 5 | I19: 5 | J19: 20 | K19: - | L19: 2 | M19: 8 | N19: =SUM(F19:I19) -> 30
A20: 11 | B20: Pendidikan Bahasa Indonesia | C20: 2024 | D20: 33 | E20: - | F20: - | G20: - | H20: - | I20: - | J20: - | K20: - | L20: - | M20: - | N20: =SUM(F20:I20) -> 0
A21: 12 | B21: Pendidikan Geografi | C21: 2024 | D21: 42 | E21: - | F21: - | G21: - | H21: - | I21: - | J21: - | K21: - | L21: - | M21: - | N21: =SUM(F21:I21) -> 0
A22: 13 | B22: Pendidikan Matematika | C22: 2024 | D22: 30 | E22: - | F22: - | G22: - | H22: - | I22: - | J22: - | K22: - | L22: - | M22: - | N22: =SUM(F22:I22) -> 0
A23: 14 | B23: Pendidikan Fisika | C23: 2024 | D23: 14 | E23: 9 | F23: - | G23: 4 | H23: - | I23: - | J23: 2 | K23: - | L23: 1 | M23: 1 | N23: =SUM(F23:I23) -> 4
A24: 15 | B24: Pendidikan Kimia | C24: 2024 | D24: 15 | E24: 14 | F24: - | G24: 9 | H24: - | I24: 5 | J24: 3 | K24: - | L24: 8 | M24: - | N24: =SUM(F24:I24) -> 14
A25: 16 | B25: Pendidikan Jasmani | C25: 2024 | D25: 47 | E25: 3 | F25: 1 | G25: 2 | H25: - | I25: - | J25: - | K25: - | L25: - | M25: - | N25: =SUM(F25:I25) -> 3
A26: 17 | B26: Pendidikan Guru Sekolah Dasar | C26: 2024 | D26: 78 | E26: 78 | F26: 70 | G26: 8 | H26: - | I26: - | J26: - | K26: - | L26: - | M26: - | N26: =SUM(F26:I26) -> 78
A27: 18 | B27: Teknik Sipil | C27: 2024 | D27: 68 | E27: 23 | F27: 3 | G27: 4 | H27: 1 | I27: 1 | J27: 0 | K27: 0 | L27: 0 | M27: 0 | N27: =SUM(F27:I27) -> 9
A28: 19 | B28: Teknik Mesin | C28: 2024 | D28: 21 | E28: 5 | F28: 2 | G28: 2 | H28: 1 | I28: 0 | J28: 0 | K28: 4 | L28: 0 | M28: 1 | N28: =SUM(F28:I28) -> 5
A29: 20 | B29: Teknik Industri | C29: 2024 | D29: 27 | E29: 15 | F29: 3 | G29: 9 | H29: 1 | I29: 2 | J29: 5 | K29: 0 | L29: 9 | M29: 1 | N29: =SUM(F29:I29) -> 15
A30: 21 | B30: Informatika | C30: 2024 | D30: 63 | E30: 0 | F30: 0 | G30: 0 | H30: 0 | I30: 0 | J30: 0 | K30: 0 | L30: 0 | M30: 0 | N30: =SUM(F30:I30) -> 0
A31: 22 | B31: Matematika | C31: 2024 | D31: 23 | E31: 3 | F31: 0 | G31: 3 | H31: 0 | I31: 0 | J31: 3 | K31: 0 | L31: 0 | M31: 0 | N31: =SUM(F31:I31) -> 3
A32: 23 | B32: Fisika | C32: 2024 | D32: 32 | E32: 1 | F32: 0 | G32: 1 | H32: 0 | I32: 0 | J32: 1 | K32: 0 | L32: 0 | M32: 0 | N32: =SUM(F32:I32) -> 1
A33: 24 | B33: Biologi | C33: 2024 | D33: 23 | E33: 6 | F33: 0 | G33: 0 | H33: 0 | I33: 6 | J33: 1 | K33: 4 | L33: 0 | M33: 1 | N33: =SUM(F33:I33) -> 6
A34: 25 | B34: Kimia | C34: 2024 | D34: 7 | E34: 13 | F34: 3 | G34: 0 | H34: 0 | I34: 0 | J34: 7 | K34: 3 | L34: 0 | M34: 0 | N34: =SUM(F34:I34) -> 3
A35: 26 | B35: Geofisika | C35: 2024 | D35: 0 | E35: 0 | F35: 0 | G35: 0 | H35: 0 | I35: 0 | J35: 0 | K35: 0 | L35: 0 | M35: 0 | N35: =SUM(F35:I35) -> 0
A36: Jumlah | D36: =SUM(D10:D35) -> 1225 | E36: 699 | F36: 78 | G36: 86 | H36: 16 | I36: 32 | J36: 298 | K36: 45 | L36: 59 | M36: 97 | N36: =SUM(F36:I36) -> 212 | O36: data di olah
D37: min resp. | E37: =D36*75% -> 918.75 | F37: =SUM(F36:I36) -> 212
J39: Langsa,
J40: Mengetahui
J43: (…………………………………)
J44: NIP.

Sheet PERHIT-IKU 1A.
A2: FAKULTAS : | M2: IKU 1A
A8: No | B8: Program Studi | C8: Tahun Kelulusan | D8: Jumlah Lulusan | E8: Jumlah Responden | F8: Jumlah lulusan yang berhasil mendapat pekerjaan | J8: Tempat Kerja | N8: Jumlah
F9: Masa Tunggu ≤ 6 Bulan | H9: Masa Tunggu > 6 s.d. 12 Bulan | J9: Swasta | K9: Nirlaba | L9: Institusi/ organisasi Multilateral | M9: Lembaga Pemerintah/BUMD/BUMN
F10: Besaran Gaji ≥ 1,2 Kali UMP | G10: Besaran Gaji < 1,2 UMP | H10: Besaran Gaji ≥ 1,2 Kali UMP | I10: Besaran Gaji < 1,2 UMP
A11: 1 | B11: Hukum | C11: 2024 | D11: 94 | E11: 93 | F11: 20 | G11: 1 | H11: 44 | I11: 4 | J11: 13 | K11: 23 | L11: 1 | M11: 4 | N11: =SUM(F11:I11) -> 69
A12: 2 | B12: Manajemen | C12: 2024 | D12: 108 | E12: 61 | F12: 8 | G12: 12 | H12: 1 | I12: 0 | J12: 12 | K12: 3 | L12: 0 | M12: 6 | N12: =SUM(F12:I12) -> 21
A13: 3 | B13: Ekonomi Pembangunan | C13: 2024 | D13: 111 | E13: 23 | F13: 6 | G13: 6 | H13: 0 | I13: 0 | J13: 4 | K13: 1 | L13: 0 | M13: 3 | N13: =SUM(F13:I13) -> 12
A14: 4 | B14: Akuntansi | C14: 2024 | D14: 69 | E14: 38 | F14: 3 | G14: 7 | H14: 1 | I14: 2 | J14: 7 | K14: 1 | L14: 0 | M14: 6 | N14: =SUM(F14:I14) -> 13
A15: 5 | B15: Agroteknologi | C15: 2024 | D15: 53 | E15: 27 | F15: 10 | G15: 7 | H15: 0 | I15: 5 | J15: 13 | K15: 1 | L15: 0 | M15: 4 | N15: =SUM(F15:I15) -> 22
A16: 6 | B16: Agribisnis | C16: 2024 | D16: 51 | E16: 51 | F16: 6 | G16: 13 | H16: 2 | I16: 15 | J16: 29 | K16: 2 | L16: 1 | M16: 4 | N16: =SUM(F16:I16) -> 36
A17: 7 | B17: Akuakultur | C17: 2024 | D17: 24 | E17: 16 | F17: 1 | G17: 2 | H17: 0 | I17: 0 | J17: 2 | K17: 0 | L17: 0 | M17: 1 | N17: =SUM(F17:I17) -> 3
A18: 8 | B18: Pendidikan Sejarah | C18: 2024 | D18: 62 | E18: 35 | F18: 8 | G18: 10 | H18: 7 | I18: 10 | J18: 5 | K18: - | L18: - | M18: 25 | N18: =SUM(F18:I18) -> 35
A19: 9 | B19: Pendidikan Biologi | C19: 2024 | D19: 72 | E19: 56 | F19: 2 | G19: 7 | H19: - | I19: - | J19: - | K19: 2 | L19: 2 | M19: 3 | N19: =SUM(F19:I19) -> 9
A20: 10 | B20: Pendidikan Bahasa Inggris | C20: 2024 | D20: 58 | E20: 30 | F20: 5 | G20: 15 | H20: 5 | I20: 5 | J20: 20 | K20: - | L20: 2 | M20: 8 | N20: =SUM(F20:I20) -> 30
A21: 11 | B21: Pendidikan Bahasa Indonesia | C21: 2024 | D21: 33 | E21: - | F21: - | G21: - | H21: - | I21: - | J21: - | K21: - | L21: - | M21: - | N21: =SUM(F21:I21) -> 0
A22: 12 | B22: Pendidikan Geografi | C22: 2024 | D22: 42 | E22: - | F22: - | G22: - | H22: - | I22: - | J22: - | K22: - | L22: - | M22: - | N22: =SUM(F22:I22) -> 0
A23: 13 | B23: Pendidikan Matematika | C23: 2024 | D23: 30 | E23: - | F23: - | G23: - | H23: - | I23: - | J23: - | K23: - | L23: - | M23: - | N23: =SUM(F23:I23) -> 0
A24: 14 | B24: Pendidikan Fisika | C24: 2024 | D24: 14 | E24: 9 | F24: - | G24: 4 | H24: - | I24: - | J24: 2 | K24: - | L24: 1 | M24: 1 | N24: =SUM(F24:I24) -> 4
A25: 15 | B25: Pendidikan Kimia | C25: 2024 | D25: 15 | E25: 14 | F25: - | G25: 9 | H25: - | I25: 5 | J25: 3 | K25: - | L25: 8 | M25: - | N25: =SUM(F25:I25) -> 14
A26: 16 | B26: Pendidikan Jasmani | C26: 2024 | D26: 47 | E26: 3 | F26: 1 | G26: 2 | H26: - | I26: - | J26: - | K26: - | L26: - | M26: - | N26: =SUM(F26:I26) -> 3
A27: 17 | B27: Pendidikan Guru Sekolah Dasar | C27: 2024 | D27: 78 | E27: 78 | F27: 70 | G27: 8 | H27: - | I27: - | J27: - | K27: - | L27: - | M27: - | N27: =SUM(F27:I27) -> 78
A28: 18 | B28: Teknik Sipil | C28: 2024 | D28: 68 | E28: 23 | F28: 3 | G28: 4 | H28: 1 | I28: 1 | J28: 0 | K28: 0 | L28: 0 | M28: 0 | N28: =SUM(F28:I28) -> 9
A29: 19 | B29: Teknik Mesin | C29: 2024 | D29: 21 | E29: 5 | F29: 2 | G29: 2 | H29: 1 | I29: 0 | J29: 0 | K29: 4 | L29: 0 | M29: 1 | N29: =SUM(F29:I29) -> 5
A30: 20 | B30: Teknik Industri | C30: 2024 | D30: 27 | E30: 15 | F30: 3 | G30: 9 | H30: 1 | I30: 2 | J30: 5 | K30: 0 | L30: 9 | M30: 1 | N30: =SUM(F30:I30) -> 15
A31: 21 | B31: Informatika | C31: 2024 | D31: 63 | E31: 0 | F31: 0 | G31: 0 | H31: 0 | I31: 0 | J31: 0 | K31: 0 | L31: 0 | M31: 0 | N31: =SUM(F31:I31) -> 0
A32: 22 | B32: Matematika | C32: 2024 | D32: 23 | E32: 3 | F32: 0 | G32: 3 | H32: 0 | I32: 0 | J32: 3 | K32: 0 | L32: 0 | M32: 0 | N32: =SUM(F32:I32) -> 3
A33: 23 | B33: Fisika | C33: 2024 | D33: 32 | E33: 1 | F33: 0 | G33: 1 | H33: 0 | I33: 0 | J33: 1 | K33: 0 | L33: 0 | M33: 0 | N33: =SUM(F33:I33) -> 1
A34: 24 | B34: Biologi | C34: 2024 | D34: 23 | E34: 6 | F34: 0 | G34: 0 | H34: 0 | I34: 6 | J34: 1 | K34: 4 | L34: 0 | M34: 1 | N34: =SUM(F34:I34) -> 6
A35: 25 | B35: Kimia | C35: 2024 | D35: 7 | E35: 13 | F35: 3 | G35: 0 | H35: 0 | I35: 0 | J35: 7 | K35: 3 | L35: 0 | M35: 0 | N35: =SUM(F35:I35) -> 3
A36: 26 | B36: Geofisika | C36: 2024 | D36: 0 | E36: 0 | F36: 0 | G36: 0 | H36: 0 | I36: 0 | J36: 0 | K36: 0 | L36: 0 | M36: 0 | N36: =SUM(F36:I36) -> 0
A37: Jumlah | D37: 1225 | E37: 699 | F37: 265 | G37: 141 | H37: 20 | I37: 116 | J37: 118 | K37: 34 | L37: 46 | M37: 65 | N37: =SUM(F37:I37) -> 542
B38: PERHITUNGAN IKU 1A | E38: =SUM(F38:I38) -> 62.618026 | F38: =((F37*F39)/E37)*100 -> 37.911302 | G38: =(G37*G39)/E37*100 -> 14.120172 | H38: =H37*H39/E37*100 -> 2.2889843 | I38: =I37*I39/E37*100 -> 8.297568
A39: Jumlah Responden Minimum | C39: =D37/(D37*(2.5%*2.5%)+1) -> 693.80531 | F39: 1 | G39: 0.7 | H39: 0.8 | I39: 0.5 | K39: =SUM(F37:I37) -> 542
D40: =(C39/D37)*100 -> 56.637168 | E40: =D37*75% -> 918.75 | F40: k1 | G40: k2 | H40: k3 | I40: k4
B41: Jenis Hitungan | C41: Bobot Hitungan | D41: Hasil Hitungan
B42: Masa Tunggu ≤ 6 Bulan Besaran Gaji ≥ 1,2 Kali UMP | C42: 1 | D42: =((F37*F39)/E37)*100 -> 37.911302
B43: Masa Tunggu ≤ 6 Bulan Besaran Gaji ≤ 1,2 Kali UMP | C43: 0.7 | D43: =(G37*G39)/E37*100 -> 14.120172
B44: Masa Tunggu > 6 s.d. 12 Bulan Besaran Gaji ≥ 1,2 Kali UMP | C44: 0.8 | D44: =H37*H39/E37*100 -> 2.2889843
B45: Masa Tunggu > 6 s.d. 12 Bulan Besaran Gaji ≤ 1,2 Kali UMP | C45: 0.5 | D45: =I37*I39/E37*100 -> 8.297568
B46: Total Hasil Hitungan IKU 1.A | D46: =(D42+D43+D44+D45) -> 62.618026
...

Sheet IKU 1B.
A6: No. | B6: Program Studi | C6: Tahun Lulus | D6: Jumlah Lulusan | E6: Jumlah Responden | F6: Jumlah Lulusan S1 Yang Berhasil Melanjutkan Studi | I6: Jumlah
F7: Program Profesi | G7: Melanjutkan S 2 | H7: Melanjutkan S 3
A8: 1 | B8: Hukum | C8: 2024 | D8: 94 | E8: 93 | F8: 0 | G8: 3 | H8: 0 | I8: =SUM(F8:H8) -> 3
A9: 2 | B9: Manajemen | C9: 2024 | D9: 108 | E9: 61 | F9: 0 | G9: 1 | H9: 0 | I9: =SUM(F9:H9) -> 1
A10: 3 | B10: Ekonomi Pembangunan | C10: 2024 | D10: 111 | E10: 23 | F10: 0 | G10: 2 | H10: 0 | I10: =SUM(F10:H10) -> 2
A11: 4 | B11: Akuntansi | C11: 2024 | D11: 69 | E11: 38 | F11: 0 | G11: 0 | H11: 0 | I11: =SUM(F11:H11) -> 0
A12: 5 | B12: Agroteknologi | C12: 2024 | D12: 53 | E12: 27 | F12: 0 | G12: 1 | H12: 0 | I12: =SUM(F12:H12) -> 1
A13: 6 | B13: Agribisnis | C13: 2024 | D13: 51 | E13: 51 | F13: 0 | G13: 2 | H13: 0 | I13: =SUM(F13:H13) -> 2
A14: 7 | B14: Akuakultur | C14: 2024 | D14: 24 | E14: 16 | F14: 0 | G14: 1 | H14: 0 | I14: =SUM(F14:H14) -> 1
A15: 8 | B15: Pendidikan Sejarah | C15: 2024 | D15: 62 | E15: 35 | F15: - | G15: 2 | H15: - | I15: =SUM(F15:H15) -> 2
A16: 9 | B16: Pendidikan Biologi | C16: 2024 | D16: 72 | E16: 56 | F16: 2 | G16: 3 | H16: 1 | I16: =SUM(F16:H16) -> 6
A17: 10 | B17: Pendidikan Bahasa Inggris | C17: 2024 | D17: 58 | E17: 30 | F17: - | G17: - | H17: - | I17: =SUM(F17:H17) -> 0
A18: 11 | B18: Pendidikan Bahasa Indonesia | C18: 2024 | D18: 33 | E18: - | F18: - | G18: - | H18: - | I18: =SUM(F18:H18) -> 0
A19: 12 | B19: Pendidikan Geografi | C19: 2024 | D19: 42 | E19: - | F19: - | G19: - | H19: - | I19: =SUM(F19:H19) -> 0
A20: 13 | B20: Pendidikan Matematika | C20: 2024 | D20: 30 | E20: - | F20: - | G20: - | H20: - | I20: =SUM(F20:H20) -> 0
A21: 14 | B21: Pendidikan Fisika | C21: 2024 | D21: 14 | E21: 9 | F21: - | G21: - | H21: - | I21: =SUM(F21:H21) -> 0
A22: 15 | B22: Pendidikan Kimia | C22: 2024 | D22: 15 | E22: 14 | G22: 1 | I22: =SUM(F22:H22) -> 1
A23: 16 | B23: Pendidikan Jasmani | C23: 2024 | D23: 47 | F23: - | G23: - | H23: - | I23: =SUM(F23:H23) -> 0
A24: 17 | B24: Pendidikan Guru Sekolah Dasar | C24: 2024 | D24: 78 | E24: 121 | F24: 50 | G24: 4 | I24: =SUM(F24:H24) -> 54
A25: 18 | B25: Teknik Sipil | C25: 2024 | D25: 68 | E25: 23 | F25: 0 | G25: 0 | H25: 0 | I25: =SUM(F25:H25) -> 0
A26: 19 | B26: Teknik Mesin | C26: 2024 | D26: 21 | E26: 5 | F26: 0 | G26: 0 | H26: 0 | I26: =SUM(F26:H26) -> 0
A27: 20 | B27: Teknik Industri | C27: 2024 | D27: 27 | E27: 15 | F27: 0 | G27: 1 | H27: 0 | I27: =SUM(F27:H27) -> 1
A28: 21 | B28: Informatika | C28: 2024 | D28: 63 | E28: 0 | F28: 0 | G28: 0 | H28: 0 | I28: =SUM(F28:H28) -> 0
A29: 22 | B29: Matematika | C29: 2024 | D29: 23 | E29: 3 | F29: 0 | G29: 0 | H29: 0 | I29: =SUM(F29:H29) -> 0
A30: 23 | B30: Fisika | C30: 2024 | D30: 32 | E30: 1 | F30: 0 | G30: 0 | H30: 0 | I30: =SUM(F30:H30) -> 0
A31: 24 | B31: Biologi | C31: 2024 | D31: 23 | E31: 6 | F31: 0 | G31: 0 | H31: 0 | I31: =SUM(F31:H31) -> 0
A32: 25 | B32: Kimia | C32: 2024 | D32: 7 | E32: 13 | F32: 0 | G32: 0 | H32: 0 | I32: =SUM(F32:H32) -> 0
A33: 26 | B33: Geofisika | C33: 2024 | D33: 0 | E33: 0 | F33: 0 | G33: 0 | H33: 0 | I33: =SUM(F33:H33) -> 0
A34: Jumlah | D34: =SUM(D8:D33) -> 1225 | E34: 699 | F34: 72 | G34: 34 | H34: 3 | I34: =SUM(F34:H34) -> 109
H44: Langsa,
H45: Mengetahui
H48: (…………………………………)
H49: NIP.
B52: Jumlah Responden Minimum | C52: =D34/(D34*(2.5%*2.5%)+1) -> 693.80531
B54: Jenis Hitungan IKU 1.C | C54: Bobot Hitungan | D54: Hasil Hitungan
B55: Melanjutkan Studi | C55: 1 | D55: =((I34*C55)/E34)*100 -> 15.593705

Sheet PERHIT IKU 1B.
A6: No. | B6: Program Studi | C6: Tahun Lulus | D6: Jumlah Lulusan | E6: Jumlah Responden | F6: Jumlah Lulusan S1 Yang Berhasil Melanjutkan Studi | I6: Jumlah
F7: Program Profesi | G7: Melanjutkan S 2 | H7: Melanjutkan S 3
A8: 1 | B8: Hukum | C8: 2024 | D8: 94 | E8: 93 | F8: 0 | G8: 3 | H8: 0 | I8: =SUM(F8:H8) -> 3
A9: 2 | B9: Manajemen | C9: 2024 | D9: 108 | E9: 61 | F9: 0 | G9: 1 | H9: 0 | I9: =SUM(F9:H9) -> 1
A10: 3 | B10: Ekonomi Pembangunan | C10: 2024 | D10: 111 | E10: 23 | F10: 0 | G10: 2 | H10: 0 | I10: =SUM(F10:H10) -> 2
A11: 4 | B11: Akuntansi | C11: 2024 | D11: 69 | E11: 38 | F11: 0 | G11: 0 | H11: 0 | I11: =SUM(F11:H11) -> 0
A12: 5 | B12: Agroteknologi | C12: 2024 | D12: 53 | E12: 27 | F12: 0 | G12: 1 | H12: 0 | I12: =SUM(F12:H12) -> 1
A13: 6 | B13: Agribisnis | C13: 2024 | D13: 51 | E13: 51 | F13: 0 | G13: 2 | H13: 0 | I13: =SUM(F13:H13) -> 2
A14: 7 | B14: Akuakultur | C14: 2024 | D14: 24 | E14: 16 | F14: 0 | G14: 1 | H14: 0 | I14: =SUM(F14:H14) -> 1
A15: 8 | B15: Pendidikan Sejarah | C15: 2024 | D15: 62 | E15: 35 | F15: - | G15: 2 | H15: - | I15: =SUM(F15:H15) -> 2
A16: 9 | B16: Pendidikan Biologi | C16: 2024 | D16: 72 | E16: 56 | F16: 2 | G16: 3 | H16: 1 | I16: =SUM(F16:H16) -> 6
A17: 10 | B17: Pendidikan Bahasa Inggris | C17: 2024 | D17: 58 | E17: 30 | F17: - | G17: - | H17: - | I17: =SUM(F17:H17) -> 0
A18: 11 | B18: Pendidikan Bahasa Indonesia | C18: 2024 | D18: 33 | E18: - | F18: - | G18: - | H18: - | I18: =SUM(F18:H18) -> 0
A19: 12 | B19: Pendidikan Geografi | C19: 2024 | D19: 42 | E19: - | F19: - | G19: - | H19: - | I19: =SUM(F19:H19) -> 0
A20: 13 | B20: Pendidikan Matematika | C20: 2024 | D20: 30 | E20: - | F20: - | G20: - | H20: - | I20: =SUM(F20:H20) -> 0
A21: 14 | B21: Pendidikan Fisika | C21: 2024 | D21: 14 | E21: 9 | F21: - | G21: - | H21: - | I21: =SUM(F21:H21) -> 0
A22: 15 | B22: Pendidikan Kimia | C22: 2024 | D22: 15 | E22: 14 | G22: 1 | I22: =SUM(F22:H22) -> 1
A23: 16 | B23: Pendidikan Jasmani | C23: 2024 | D23: 47 | F23: - | G23: - | H23: - | I23: =SUM(F23:H23) -> 0
A24: 17 | B24: Pendidikan Guru Sekolah Dasar | C24: 2024 | D24: 78 | E24: 121 | F24: 50 | G24: 4 | I24: =SUM(F24:H24) -> 54
A25: 18 | B25: Teknik Sipil | C25: 2024 | D25: 68 | E25: 23 | F25: 0 | G25: 0 | H25: 0 | I25: =SUM(F25:H25) -> 0
A26: 19 | B26: Teknik Mesin | C26: 2024 | D26: 21 | E26: 5 | F26: 0 | G26: 0 | H26: 0 | I26: =SUM(F26:H26) -> 0
A27: 20 | B27: Teknik Industri | C27: 2024 | D27: 27 | E27: 15 | F27: 0 | G27: 1 | H27: 0 | I27: =SUM(F27:H27) -> 1
A28: 21 | B28: Informatika | C28: 2024 | D28: 63 | E28: 0 | F28: 0 | G28: 0 | H28: 0 | I28: =SUM(F28:H28) -> 0
A29: 22 | B29: Matematika | C29: 2024 | D29: 23 | E29: 3 | F29: 0 | G29: 0 | H29: 0 | I29: =SUM(F29:H29) -> 0
A30: 23 | B30: Biologi | C30: 2024 | D30: 32 | E30: 1 | F30: 0 | G30: 0 | H30: 0 | I30: =SUM(F30:H30) -> 0
A31: 24 | B31: Fisika | C31: 2024 | D31: 23 | E31: 6 | F31: 0 | G31: 0 | H31: 0 | I31: =SUM(F31:H31) -> 0
A32: 25 | B32: Kimia | C32: 2024 | D32: 7 | E32: 13 | F32: 0 | G32: 0 | H32: 0 | I32: =SUM(F32:H32) -> 0
A33: 26 | B33: Geofisika | C33: 2024 | D33: 0 | E33: 0 | F33: 0 | G33: 0 | H33: 0 | I33: =SUM(F33:H33) -> 0
A34: Jumlah | D34: =SUM(D8:D33) -> 1225 | E34: 699 | F34: 72 | G34: 34 | H34: 3 | I34: =SUM(F34:H34) -> 109
B35: PERHITUNGAN IKU 1B | E35: =((I34*F35)/E34)*100 -> 15.593705 | F35: 1
F36: k
H45: Langsa,
H46: Mengetahui
H49: (…………………………………)
H50: NIP.
B52: Jumlah Responden Minimum | C52: =D34/(D34*(2.5%*2.5%)+1) -> 693.80531
B54: Jenis Hitungan IKU 1.C | C54: Bobot Hitungan | D54: Hasil Hitungan
B55: Melanjutkan Studi | C55: 1 | D55: =((I34*C55)/E34)*100 -> 15.593705

Sheet IKU 1C
A6: No. | B6: Program Studi | C6: Tahun Lulus | D6: Jumlah Lulusan | E6: Jumlah Responden | F6: Lulusan Menjadi Wiraswasta | L6: Jumlah
F7: ≤ 6 Bulan* | H7: 6 Bulan s.d.≤ 12 Bulan** | J7: Jenis Pekerjaan
F8: Besaran Gaji ≥ 1,2 X UMP (Rp) | G8: Besaran Gaji < 1,2 X UMP (Rp) | H8: Besaran Gaji ≥ 1,2 X UMP (Rp) | I8: Besaran Gaji < 1,2 X UMP (Rp) | J8: Pendiri Perusahaan atau Pasangan Pendiri Perusahaan | K8: Pekerja Lepas
A9: 1 | B9: Hukum | C9: 2024 | D9: 94 | E9: 93 | F9: 20 | G9: 4 | H9: 44 | I9: 1 | J9: 28 | K9: 8 | L9: =SUM(G9:K9) -> 85
A10: 2 | B10: Manajemen | C10: 2024 | D10: 108 | E10: 61 | F10: 6 | G10: 1 | H10: 0 | I10: 0 | J10: 4 | K10: 3 | L10: =SUM(G10:K10) -> 8
A11: 3 | B11: Ekonomi Pembangunan | C11: 2024 | D11: 111 | E11: 23 | F11: 1 | G11: 0 | H11: 1 | I11: 1 | J11: 3 | K11: 0 | L11: =SUM(G11:K11) -> 5
A12: 4 | B12: Akuntansi | C12: 2024 | D12: 69 | E12: 38 | F12: 1 | G12: 2 | H12: 0 | I12: 1 | J12: 2 | K12: 2 | L12: =SUM(G12:K12) -> 7
A13: 5 | B13: Agroteknologi | C13: 2024 | D13: 53 | E13: 27 | F13: 0 | G13: 1 | H13: 0 | I13: 0 | J13: 1 | K13: 0 | L13: =SUM(G13:K13) -> 2
A14: 6 | B14: Agribisnis | C14: 2024 | D14: 51 | E14: 51 | F14: 8 | G14: 10 | H14: 3 | I14: 8 | J14: 12 | K14: 17 | L14: =SUM(G14:K14) -> 50
A15: 7 | B15: Akuakultur | C15: 2024 | D15: 24 | E15: 16 | F15: 1 | G15: 2 | H15: 0 | I15: 0 | J15: 0 | K15: 2 | L15: =SUM(G15:K15) -> 4
A16: 8 | B16: Pendidikan Sejarah | C16: 2024 | D16: 62 | E16: 35 | F16: - | G16: 5 | H16: - | I16: 3 | J16: - | K16: 5 | L16: =SUM(G16:K16) -> 13
A17: 9 | B17: Pendidikan Biologi | C17: 2024 | D17: 72 | E17: 56 | F17: 5 | G17: 3 | H17: 3 | I17: 2 | J17: - | K17: 5 | L17: =SUM(G17:K17) -> 13
A18: 10 | B18: Pendidikan Bahasa Inggris | C18: 2024 | D18: 58 | E18: 30 | F18: 5 | G18: 15 | H18: 5 | I18: 5 | J18: 20 | K18: 10 | L18: =SUM(G18:K18) -> 55
A19: 11 | B19: Pendidikan Bahasa Indonesia | C19: 2024 | D19: 33 | E19: - | L19: =SUM(G19:K19) -> 0
A20: 12 | B20: Pendidikan Geografi | C20: 2024 | D20: 42 | E20: - | L20: =SUM(G20:K20) -> 0
A21: 13 | B21: Pendidikan Matematika | C21: 2024 | D21: 30 | E21: - | L21: =SUM(G21:K21) -> 0
A22: 14 | B22: Pendidikan Fisika | C22: 2024 | D22: 14 | E22: 9 | F22: - | G22: 2 | H22: - | I22: - | J22: 1 | K22: 1 | L22: =SUM(G22:K22) -> 4
A23: 15 | B23: Pendidikan Kimia | C23: 2024 | D23: 15 | E23: 14 | F23: - | G23: - | H23: - | I23: - | J23: - | K23: 3 | L23: =SUM(G23:K23) -> 3
A24: 16 | B24: Pendidikan Jasmani | C24: 2024 | D24: 47 | F24: - | G24: - | H24: - | I24: - | J24: - | K24: - | L24: =SUM(G24:K24) -> 0
A25: 17 | B25: Pendidikan Guru Sekolah Dasar | C25: 2024 | D25: 78 | E25: 121 | F25: - | G25: - | H25: 5 | I25: - | J25: - | K25: - | L25: =SUM(G25:K25) -> 5
A26: 18 | B26: Teknik Sipil | C26: 2024 | D26: 68 | E26: 23 | F26: 0 | G26: 0 | H26: 0 | I26: 0 | J26: 0 | K26: 0 | L26: =SUM(G26:K26) -> 0
A27: 19 | B27: Teknik Mesin | C27: 2024 | D27: 21 | E27: 5 | F27: 0 | G27: 4 | H27: 0 | I27: 0 | J27: 0 | K27: 0 | L27: =SUM(G27:K27) -> 4
A28: 20 | B28: Teknik Industri | C28: 2024 | D28: 27 | E28: 15 | F28: 0 | G28: 3 | H28: 0 | I28: 0 | J28: 1 | K28: 0 | L28: =SUM(G28:K28) -> 4
A29: 21 | B29: Informatika | C29: 2024 | D29: 63 | E29: 0 | F29: 0 | G29: 0 | H29: 0 | I29: 0 | J29: 0 | K29: 0 | L29: =SUM(G29:K29) -> 0
A30: 22 | B30: Matematika | C30: 2024 | D30: 23 | E30: 3 | F30: 0 | G30: 3 | H30: 0 | I30: 0 | J30: 0 | K30: 0 | L30: =SUM(G30:K30) -> 3
A31: 23 | B31: Fisika | C31: 2024 | D31: 32 | E31: 1 | F31: 0 | G31: 0 | H31: 0 | I31: 0 | J31: 0 | K31: 0 | L31: =SUM(G31:K31) -> 0
A32: 24 | B32: Biologi | C32: 2024 | D32: 23 | E32: 6 | F32: 0 | G32: 0 | H32: 0 | I32: 1 | J32: 4 | K32: 1 | L32: =SUM(G32:K32) -> 6
A33: 25 | B33: Kimia | C33: 2024 | D33: 7 | E33: 13 | F33: 0 | G33: 0 | H33: 0 | I33: 0 | J33: 0 | K33: 0 | L33: =SUM(G33:K33) -> 0
A34: 26 | B34: Geofisika | C34: 2024 | D34: 0 | E34: 0 | F34: 0 | G34: 0 | H34: 0 | I34: 0 | J34: 0 | K34: 0 | L34: =SUM(G34:K34) -> 0
A35: Jumlah | D35: =SUM(D9:D34) -> 1225 | E35: 699 | F35: 267 | G35: 128 | H35: 101 | I35: 416 | J35: 93 | K35: 189 | L35: =SUM(F35:I35) -> 912
E36: =L35-E35 -> 213
F37: 65 | G37: 52 | H37: 32 | I37: 42 | J37: 28 | K37: 108 | L37: 327
F38: 47 | G38: 55 | H38: 61 | I38: 22 | J38: 76 | K38: 57
I39: =SUM(F38:I38) -> 185
I43: Langsa,
I44: Mengetahui
I47: (…………………………………)
I48: NIP.

Sheet PERHIT IKU 1C
A1: 1C. Data Kelulusan S1 yang menjadi wiraswasta Kurang Dari Atau Sama Dengan 12 Bulan (≤ 12 Bulan) Setelah Tanggal Terbit Ijazah
A3: No. | B3: Program Studi | C3: Tahun Lulus | D3: Jumlah Lulusan | E3: Jumlah Responden | F3: Lulusan Menjadi Wiraswasta | L3: Jumlah
F4: ≤ 6 Bulan* | H4: 6 Bulan s.d.≤ 12 Bulan** | J4: Jenis Pekerjaan
F5: Besaran Gaji ≥ 1,2 X UMP (Rp) | G5: Besaran Gaji < 1,2 X UMP (Rp) | H5: Besaran Gaji ≥ 1,2 X UMP (Rp) | I5: Besaran Gaji < 1,2 X UMP (Rp) | J5: Pendiri Perusahaan atau Pasangan Pendiri Perusahaan | K5: Pekerja Lepas
A6: 1 | B6: Hukum | C6: 2024 | D6: 94 | E6: 93 | F6: 20 | G6: 4 | H6: 44 | I6: 1 | J6: 28 | K6: 8 | L6: =SUM(G6:K6) -> 85
A7: 2 | B7: Manajemen | C7: 2024 | D7: 108 | E7: 61 | F7: 6 | G7: 1 | H7: 0 | I7: 0 | J7: 4 | K7: 3 | L7: =SUM(G7:K7) -> 8
A8: 3 | B8: Ekonomi Pembangunan | C8: 2024 | D8: 111 | E8: 23 | F8: 1 | G8: 0 | H8: 1 | I8: 1 | J8: 3 | K8: 0 | L8: =SUM(G8:K8) -> 5
A9: 4 | B9: Akuntansi | C9: 2024 | D9: 69 | E9: 38 | F9: 1 | G9: 2 | H9: 0 | I9: 1 | J9: 2 | K9: 2 | L9: =SUM(G9:K9) -> 7
A10: 5 | B10: Agroteknologi | C10: 2024 | D10: 53 | E10: 27 | F10: 0 | G10: 1 | H10: 0 | I10: 0 | J10: 1 | K10: 0 | L10: =SUM(G10:K10) -> 2
A11: 6 | B11: Agribisnis | C11: 2024 | D11: 51 | E11: 51 | F11: 8 | G11: 10 | H11: 3 | I11: 8 | J11: 12 | K11: 17 | L11: =SUM(G11:K11) -> 50
A12: 7 | B12: Akuakultur | C12: 2024 | D12: 24 | E12: 16 | F12: 1 | G12: 2 | H12: 0 | I12: 0 | J12: 0 | K12: 2 | L12: =SUM(G12:K12) -> 4
A13: 8 | B13: Pendidikan Sejarah | C13: 2024 | D13: 62 | E13: 35 | F13: - | G13: 5 | H13: - | I13: 3 | J13: - | K13: 5 | L13: =SUM(G13:K13) -> 13
A14: 9 | B14: Pendidikan Biologi | C14: 2024 | D14: 72 | E14: 56 | F14: 5 | G14: 3 | H14: 3 | I14: 2 | J14: - | K14: 5 | L14: =SUM(G14:K14) -> 13
A15: 10 | B15: Pendidikan Bahasa Inggris | C15: 2024 | D15: 58 | E15: 30 | F15: 5 | G15: 15 | H15: 5 | I15: 5 | J15: 20 | K15: 10 | L15: =SUM(G15:K15) -> 55
A16: 11 | B16: Pendidikan Bahasa Indonesia | C16: 2024 | D16: 33 | E16: - | L16: =SUM(G16:K16) -> 0
A17: 12 | B17: Pendidikan Geografi | C17: 2024 | D17: 42 | E17: - | L17: =SUM(G17:K17) -> 0
A18: 13 | B18: Pendidikan Matematika | C18: 2024 | D18: 30 | E18: - | L18: =SUM(G18:K18) -> 0
A19: 14 | B19: Pendidikan Fisika | C19: 2024 | D19: 14 | E19: 9 | F19: - | G19: 2 | H19: - | I19: - | J19: 1 | K19: 1 | L19: =SUM(G19:K19) -> 4
A20: 15 | B20: Pendidikan Kimia | C20: 2024 | D20: 15 | E20: 14 | F20: - | G20: - | H20: - | I20: - | J20: - | K20: 3 | L20: =SUM(G20:K20) -> 3
A21: 16 | B21: Pendidikan Jasmani | C21: 2024 | D21: 47 | F21: - | G21: - | H21: - | I21: - | J21: - | K21: - | L21: =SUM(G21:K21) -> 0
A22: 17 | B22: Pendidikan Guru Sekolah Dasar | C22: 2024 | D22: 78 | E22: 121 | F22: - | G22: - | H22: 5 | I22: - | J22: - | K22: - | L22: =SUM(G22:K22) -> 5
A23: 18 | B23: Teknik Sipil | C23: 2024 | D23: 68 | E23: 23 | F23: 0 | G23: 0 | H23: 0 | I23: 0 | J23: 0 | K23: 0 | L23: =SUM(G23:K23) -> 0
A24: 19 | B24: Teknik Mesin | C24: 2024 | D24: 21 | E24: 5 | F24: 0 | G24: 4 | H24: 0 | I24: 0 | J24: 0 | K24: 0 | L24: =SUM(G24:K24) -> 4
A25: 20 | B25: Teknik Industri | C25: 2024 | D25: 27 | E25: 15 | F25: 0 | G25: 3 | H25: 0 | I25: 0 | J25: 1 | K25: 0 | L25: =SUM(G25:K25) -> 4
A26: 21 | B26: Informatika | C26: 2024 | D26: 63 | E26: 0 | F26: 0 | G26: 0 | H26: 0 | I26: 0 | J26: 0 | K26: 0 | L26: =SUM(G26:K26) -> 0
A27: 22 | B27: Matematika | C27: 2024 | D27: 23 | E27: 3 | F27: 0 | G27: 3 | H27: 0 | I27: 0 | J27: 0 | K27: 0 | L27: =SUM(G27:K27) -> 3
A28: 23 | B28: Fisika | C28: 2024 | D28: 32 | E28: 1 | F28: 0 | G28: 0 | H28: 0 | I28: 0 | J28: 0 | K28: 0 | L28: =SUM(G28:K28) -> 0
A29: 24 | B29: Biologi | C29: 2024 | D29: 23 | E29: 6 | F29: 0 | G29: 0 | H29: 0 | I29: 1 | J29: 4 | K29: 1 | L29: =SUM(G29:K29) -> 6
A30: 25 | B30: Kimia | C30: 2024 | D30: 7 | E30: 13 | F30: 0 | G30: 0 | H30: 0 | I30: 0 | J30: 0 | K30: 0 | L30: =SUM(G30:K30) -> 0
A31: 26 | B31: Geofisika | C31: 2024 | D31: 0 | E31: 0 | F31: 0 | G31: 0 | H31: 0 | I31: 0 | J31: 0 | K31: 0 | L31: =SUM(G31:K31) -> 0
B32: Jumlah | D32: =SUM(D6:D31) -> 1225 | E32: 699 | F32: 57 | G32: 78 | H32: 61 | I32: 109 | J32: 93 | K32: 189 | L32: =SUM(F32:I32) -> 305
B33: PERHITUNGAN IKU 1C | E33: =SUM(F33:I33) -> 42.145923 | F33: =((F32*F35)/E32)*100 -> 9.7854077 | G33: =(G32*G35)/E32*100 -> 11.158798 | H33: =H32*H35/E32*100 -> 8.7267525 | I33: =I32*I35/E32*100 -> 12.474964
H34: =SUM(F32:I32) -> 305 | J34: =SUM(F33:I33) -> 42.145923
B35: Jumlah Responden Minimum | C35: =D32/(D32*(2.5%*2.5%)+1) -> 693.80531 | F35: 1.2 | G35: 1 | H35: 1 | I35: 0.8
F36: k1 | G36: k2 | H36: k3 | I36: k4
B37: Jenis Hitungan | C37: Bobot Hitungan | D37: Hasil Hitungan
B38: Masa Tunggu ≤ 6 Bulan Besaran Gaji ≥ 1,2 Kali UMP | D38: =((F32*F35)/E32)*100 -> 9.7854077 | F38: =F33*F35/E32*100 -> 1.6798983 | G38: =F32*F35/E32*100 -> 9.7854077
B39: Masa Tunggu ≤ 6 Bulan Besaran Gaji ≤ 1,2 Kali UMP | D39: =(G32*G35)/E32*100 -> 11.158798 | F39: =G33*G35/E32*100 -> 1.5963946
B40: Masa Tunggu > 6 s.d. 12 Bulan Besaran Gaji ≥ 1,2 Kali UMP | D40: =H32*H35/E32*100 -> 8.7267525 | F40: =H33*H35/E32*100 -> 1.2484624
B41: Masa Tunggu > 6 s.d. 12 Bulan Besaran Gaji ≤ 1,2 Kali UMP | D41: =I32*I35/E32*100 -> 12.474964 | F41: =I33*I35/E32*100 -> 1.4277498
...

Sheet PERHIT IKU 1
A1: IKU 1 target 40 persen
A3: TARGET IKU 1 | B3: 40 | C3: CAPAIAN
A4: REALISASI
A5: MAHASISWA BEKERJA | B5: ='PERHIT-IKU 1A.'!E38 -> 62.618026 | C5: =B8/B3*100 -> 43.046371 | D5: =B5+B6+B7 -> 120.35765 | E5: =D5/B3 -> 3.0089413
A6: MAHASISWA LANJUT STUDI | B6: ='PERHIT IKU 1B.'!E35 -> 15.593705 | E6: =(B8/920)*100 -> 1.8715814
A7: MAHASISWA BERWIRA USAHA | B7: ='PERHIT IKU 1C'!E33 -> 42.145923
A8: TOTAL | B8: =SUM(B5:B7)/699*100 -> 17.218548 | D8: =SUM(B5:B7) -> 120.35765

Sheet PERHIT IKU 3 dan 4
A2: IKU 3 | B2: TARGET 20
A3: TRIDHARMA | B3: =#REF! -> #REF!
A4: PRAKTISI | B4: =#REF! -> #REF!
A5: MEMBIMBING | B5: =#REF! -> #REF!
B6: =SUM(B3:B5) -> #REF!
A7: Data belum lengkap sesuai tiap nama Dosen yang memiliki NIDN. Jika dosen melakukan lebih dari satu kegiatan akan digunakan bobot yang tertinggi
D8: =32-0.11 -> 31.89
A11: IKU 4 | B11: TARGET 20 | G11: 23.7
G12: 7.57 | H12: =B6-G12 -> #REF!
A13: ='IKU 4.2'!C35 -> 30.099668 | D13: =A13-11 -> 19.099668 | G13: =G11+G12 -> 31.27
K19: =5.73+8.45 -> 14.18
K21: =7.57+0.89 -> 8.46
K23: =8.46-7.57 -> 0.89
B24: 32 dibuatnya tw 3

Sheet IKU 4.1
A1: 4.1. Kriteria Sertifikat Kompetensi/Profesi
A3: No | B3: Program Studi | C3: Total Jumlah Dosen Memiliki NIDN/NIDK | D3: Lembaga Sertifikasi Profesi (LSP) Nasional | E3: Lembaga Sertifikasi Kompetensi (LSk) | F3: Lembaga atau Asosiasi Profesi atau Sertifikasi Internasional | G3: Perusahaan Fortune 500 | H3: Dunia Usaha Dunia Industri | I3: Jumlah
A4: 1 | B4: Hukum | C4: 29 | D4: 0 | E4: 0 | F4: 0 | G4: 0 | H4: 0
A5: 2 | B5: Manajemen | C5: 20 | D5: 0 | E5: 0 | F5: 0 | G5: 0 | H5: 0
A6: 3 | B6: Ekonomi Pembangunan | C6: 13 | D6: 1 | E6: 0 | F6: 0 | G6: 0 | H6: 0
A7: 4 | B7: Akuntansi | C7: 10 | D7: 2 | E7: 9 | F7: 0 | G7: 0 | H7: 1
A8: 5 | B8: Agroteknologi | C8: 13 | D8: 0 | E8: 3 | F8: 0 | G8: 0 | H8: 0
A9: 6 | B9: Agribisnis | C9: 12 | D9: 0 | E9: 1 | F9: 0 | G9: 0 | H9: 1 | K9: =8.3/100*12 -> 0.996
A10: 7 | B10: Akuakultur | C10: 8 | D10: 1 | E10: 0 | F10: 0 | G10: 0 | H10: 0
A11: 8 | B11: Pendidikan Sejarah | C11: 16 | D11: 14 | E11: 0 | F11: 0 | G11: 0 | H11: 0
A12: 9 | B12: Pendidikan Biologi | C12: 19 | D12: 3 | E12: 2 | F12: 2 | G12: 0 | H12: 0
A13: 10 | B13: Pendidikan Bahasa Inggris | C13: 20 | D13: 0 | E13: 3 | F13: 0 | G13: 0 | H13: 0
A14: 11 | B14: Pendidikan Bahasa Indonesia | C14: 9 | D14: 3 | E14: 3 | F14: 0 | G14: 0 | H14: 0
A15: 12 | B15: Pendidikan Geografi | C15: 12 | D15: 0 | E15: 0 | F15: 0 | G15: 0 | H15: 0
A16: 13 | B16: Pendidikan Matematika | C16: 9 | D16: 0 | E16: 1 | F16: 0 | G16: 0 | H16: 0
A17: 14 | B17: Pendidikan Fisika | C17: 6 | D17: 0 | E17: 1 | F17: 6 | G17: 0 | H17: 0
A18: 15 | B18: Pendidikan Kimia | C18: 10 | D18: 0 | E18: 3 | F18: 0 | G18: 0 | H18: 0
A19: 16 | B19: Pendidikan Jasmani | C19: 9 | D19: 0 | E19: 0 | F19: 0 | G19: 0 | H19: 0
A20: 17 | B20: Pendidikan Guru Sekolah Dasar | D20: 10 | E20: 5 | F20: 2 | G20: 0 | H20: 0
A21: 18 | B21: Teknik Sipil | C21: 16 | D21: 14 | E21: 0 | F21: 7 | G21: 0 | H21: 0 | I21: 21
A22: 19 | B22: Teknik Mesin | C22: 15 | D22: 4 | E22: 0 | F22: 5 | G22: 0 | H22: 0 | I22: 9
A23: 20 | B23: Teknik Industri | C23: 9 | D23: 6 | E23: 0 | F23: 0 | G23: 0 | H23: 0 | I23: 6
A24: 21 | B24: Informatika | C24: 9 | D24: 3 | E24: 0 | F24: 4 | G24: 0 | H24: 0 | I24: 7
A25: 22 | B25: Matematika | C25: 7 | D25: 1 | E25: 0 | F25: 0 | G25: 0 | H25: 0 | I25: 1
A26: 23 | B26: Biologi | C26: 12 | D26: 2 | E26: 1 | F26: 0 | G26: 0 | H26: 0 | I26: 3
A27: 24 | B27: Fisika | C27: 10 | D27: 5 | E27: 0 | F27: 0 | G27: 0 | H27: 0 | I27: 5
A28: 25 | B28: Kimia | C28: 8 | D28: 4 | E28: 0 | F28: 0 | G28: 0 | H28: 0 | I28: 4
B29: Geofisika | C29: 0 | D29: 0 | E29: 0 | F29: 0 | G29: 0 | H29: 0 | I29: 0
B30: Jumlah | C30: =SUM(C4:C29) -> 301 | D30: =SUM(D4:D29) -> 73 | E30: =SUM(E4:E29) -> 32 | F30: =SUM(F4:F29) -> 26 | G30: =SUM(G4:G29) -> 0 | H30: =SUM(H4:H29) -> 2 | I30: =SUM(D30:G30) -> 131
C32: =SUM(C4:C12) -> 140
D216: =SUM(D4:D12) -> 21 | I216: =SUM(I4:I12) -> 0
E217: =SUM(E5:E13) -> 18 | F217: =SUM(F5:F13) -> 2 | G217: =SUM(G5:G13) -> 0 | H217: =SUM(H5:H13) -> 2

Sheet IKU 4.2
A1: 4.2. Kriteria Pengajar Yang Berasal Dari kalangan Praktisi
A2: NO. | B2: PRODI | C2: Total Jumlah Dosen Memiliki NIDN/NIDK | D2: Jumlah Pengajar Yang Berasal Dari Kalangan Praktisi Profesional, Dunia Industri, atau Dunia Kerja | G2: Jumlah
D3: BEKERJA DI PERUSAHAAN | E3: MENJADI WIRASWASTA PENDIRI (FOUNDER) ATAU PASANGAN PENDLRI (CO-FOUNDER) | F3: MENJADI PEKERJA LEPAS (FREELANCER)
A4: 1 | B4: Hukum | C4: 29 | D4: 3 | E4: 0 | F4: 0
A5: =A4+1 -> 2 | B5: Manajemen | C5: 20 | D5: 0 | E5: 0 | F5: 0
A6: =A5+1 -> 3 | B6: Ekonomi Pembangunan | C6: 13 | D6: 1 | E6: 0 | F6: 0
A7: =A6+1 -> 4 | B7: Akuntansi | C7: 10 | D7: 4 | E7: 0 | F7: 0
A8: =A7+1 -> 5 | B8: Agroteknologi | C8: 13 | D8: 0 | E8: 0 | F8: 0
A9: =A8+1 -> 6 | B9: Agribisnis | C9: 12 | D9: 0 | E9: 3 | F9: 0
A10: =A9+1 -> 7 | B10: Akuakultur | C10: 8 | D10: 0 | E10: 0 | F10: 0
A11: =A10+1 -> 8 | B11: Pendidikan Sejarah | C11: 16 | D11: 0 | E11: 0 | F11: 1
A12: =A11+1 -> 9 | B12: Pendidikan Biologi | C12: 19 | D12: 0 | E12: 0 | F12: 0
A13: =A12+1 -> 10 | B13: Pendidikan Bahasa Inggris | C13: 20 | D13: 0 | E13: 0 | F13: 0
A14: =A13+1 -> 11 | B14: Pendidikan Bahasa Indonesia | C14: 9 | D14: 1 | E14: 0 | F14: 0
A15: =A14+1 -> 12 | B15: Pendidikan Geografi | C15: 12 | D15: 0 | E15: 0 | F15: 0
A16: =A15+1 -> 13 | B16: Pendidikan Matematika | C16: 0 | D16: 0 | E16: 0 | F16: 0
... A28: =A27+1 -> 25 | B28: Kimia | C28: 8 | D28: 1 | E28: 0 | F28: 0
B29: Geofisika | C29: 0 | D29: 0 | E29: 0 | F29: 0
C30: =SUM(C4:C29) -> 269 | D30: =SUM(D4:D29) -> 23 | E30: =SUM(E4:E29) -> 6 | F30: =SUM(F4:F29) -> 1 | G30: 30
B34: Jenis IKU | C34: Hasil IKU 4
B35: Dosen Sertifikasi Kompetensi/Profesi | C35: =('IKU 4.1'!I30/301*60)+('IKU 4.2'!G30/301*40) -> 30.099668

Sheet Sheet1

Sheet Sheet2

Sheet Sheet3

Sheet PERHIT IKU 2A.10SKS
A1: FAKULTAS : | M1: IKU 2A
A6: No | B6: Program Studi | C6: Jumlah Mahasiswa yang Memenuhi Syarat Menjalankan Kegiatan MBKM | D6: Lulusan S 1 Yang Menghabiskan ≥ 10 ≤ 20 SKS di Luar Program Studi
D7: Magang atau praktik kerja | E7: Proyek di Desa | F7: Mengajar di Sekolah | G7: Pertukaran Pelajar | I7: Penelitian atau Riset | J7: Kegiatan Wirausaha | K7: Studi atau proyek Indenpenden | L7: Proyek Kemanusiaan | M7: Bela Negara | N7: Jumlah
G8: Inbound | H8: Outbound
A9: 1 | B9: Hukum | C9: 29 | D9: 11 | E9: 0 | F9: 0 | G9: 3 | H9: 10 | I9: 5 | J9: 0 | K9: 0 | L9: 0 | M9: 0 | N9: =SUM(D9:M9) -> 29
A10: 2 | B10: Manajemen | C10: 107 | D10: 9 | E10: 0 | F10: 0 | G10: 0 | H10: 0 | I10: 0 | J10: 0 | K10: 0 | L10: 0 | M10: 0 | N10: =SUM(D10:M10) -> 9
A11: 3 | B11: Ekonomi Pembangunan | C11: 57 | D11: 4 | E11: 0 | F11: 0 | G11: 0 | H11: 0 | I11: 6 | J11: 0 | K11: 0 | L11: 0 | M11: 0 | N11: =SUM(D11:M11) -> 10
A12: 4 | B12: Akuntansi | C12: 45 | D12: 1 | E12: 0 | F12: 0 | G12: 0 | H12: 0 | I12: 7 | J12: 0 | K12: 0 | L12: 0 | M12: 0 | N12: =SUM(D12:M12) -> 8
A13: 5 | B13: Agroteknologi | C13: 36 | D13: 0 | E13: 0 | F13: 0 | G13: 0 | H13: 9 | I13: 0 | J13: 0 | K13: 0 | L13: 0 | M13: 0 | N13: =SUM(D13:M13) -> 9
A14: 6 | B14: Agribisnis | C14: 175 | D14: 3 | E14: 5 | F14: 0 | G14: 12 | H14: 3 | I14: 5 | J14: 3 | K14: 11 | L14: 0 | M14: 0 | N14: =SUM(D14:M14) -> 42
A15: 7 | B15: Akuakultur | C15: 19 | D15: 16 | E15: 0 | F15: 0 | G15: 0 | H15: 0 | I15: 0 | J15: 0 | K15: 0 | L15: 0 | M15: 0 | N15: =SUM(D15:M15) -> 16
A16: 8 | B16: Pendidikan Sejarah | C16: 173 | D16: - | E16: - | F16: - | G16: 2 | H16: 5 | I16: - | J16: - | K16: - | L16: - | M16: - | N16: =SUM(D16:M16) -> 7
A17: 9 | B17: Pendidikan Biologi | C17: 48 | D17: - | E17: - | F17: - | G17: - | H17: - | I17: 3 | J17: - | K17: - | L17: - | M17: - | N17: =SUM(D17:M17) -> 3
A18: 10 | B18: Pendidikan Bahasa Inggris | C18: 70 | D18: - | E18: - | F18: - | G18: - | H18: - | I18: - | J18: - | K18: - | L18: - | M18: - | N18: =SUM(D18:M18) -> 0
A19: 11 | B19: Pendidikan Bahasa Indonesia | C19: 30 | D19: - | E19: - | F19: - | G19: - | H19: - | I19: - | J19: - | K19: - | L19: - | M19: - | N19: =SUM(D19:M19) -> 0
A20: 12 | B20: Pendidikan Geografi | D20: - | E20: - | F20: - | G20: - | H20: - | I20: - | J20: - | K20: - | L20: - | M20: - | N20: =SUM(D20:M20) -> 0
A21: 13 | B21: Pendidikan Matematika | D21: - | E21: - | F21: - | G21: - | H21: - | I21: - | J21: - | K21: - | L21: - | M21: - | N21: =SUM(D21:M21) -> 0
A22: 14 | B22: Pendidikan Fisika | C22: 68 | D22: - | E22: - | F22: - | G22: - | H22: - | I22: - | J22: - | K22: - | L22: - | M22: - | N22: =SUM(D22:M22) -> 0
A23: 15 | B23: Pendidikan Kimia | C23: 11 | D23: - | E23: - | F23: 5 | G23: - | H23: - | I23: - | J23: - | K23: - | L23: - | M23: - | N23: =SUM(D23:M23) -> 5
A24: 16 | B24: Pendidikan Jasmani | D24: - | E24: - | F24: - | G24: - | H24: - | I24: - | J24: - | K24: - | L24: - | M24: - | N24: =SUM(D24:M24) -> 0
A25: 17 | B25: Pendidikan Guru Sekolah Dasar | C25: 278 | D25: 1 | E25: - | F25: 15 | G25: - | H25: - | I25: - | J25: - | K25: - | L25: - | M25: - | N25: =SUM(D25:M25) -> 16
A26: 18 | B26: Teknik Sipil | C26: 53 | D26: 1 | E26: 0 | F26: 0 | G26: 0 | H26: 0 | I26: 0 | J26: 0 | K26: 4 | L26: 0 | M26: 0 | N26: =SUM(D26:M26) -> 5
A27: 19 | B27: Teknik Mesin | C27: 52 | D27: 0 | E27: 1 | F27: 0 | G27: 0 | H27: 0 | I27: 0 | J27: 0 | K27: 3 | L27: 0 | M27: 0 | N27: =SUM(D27:M27) -> 4
A28: 20 | B28: Teknik Industri | C28: 78 | D28: 0 | E28: 0 | F28: 0 | G28: 0 | H28: 0 | I28: 0 | J28: 0 | K28: 0 | L28: 0 | M28: 0 | N28: =SUM(D28:M28) -> 0
A29: 21 | B29: Informatika | C29: 70 | D29: 0 | E29: 0 | F29: 0 | G29: 0 | H29: 0 | I29: 0 | J29: 0 | K29: 0 | L29: 0 | M29: 0 | N29: =SUM(D29:M29) -> 0
A30: 22 | B30: Matematika | C30: 68 | D30: 0 | E30: 0 | F30: 0 | G30: 0 | H30: 0 | I30: 0 | J30: 0 | K30: 0 | L30: 0 | M30: 0 | N30: =SUM(D30:M30) -> 0
A31: 23 | B31: Fisika | C31: 26 | D31: 4 | E31: 0 | F31: 0 | G31: 0 | H31: 0 | I31: 0 | J31: 0 | K31: 0 | L31: 0 | M31: 0 | N31: =SUM(D31:M31) -> 4
A32: 24 | B32: Biologi | C32: 46 | D32: 0 | E32: 0 | F32: 0 | G32: 0 | H32: 0 | I32: 0 | J32: 0 | K32: 0 | L32: 0 | M32: 0 | N32: =SUM(D32:M32) -> 0
A33: 25 | B33: Kimia | C33: 31 | D33: 0 | E33: 0 | F33: 0 | G33: 0 | H33: 0 | I33: 0 | J33: 0 | K33: 0 | L33: 0 | M33: 0 | N33: =SUM(D33:M33) -> 0
A34: 26 | B34: Geofisika | C34: 0 | D34: 0 | E34: 0 | F34: 0 | G34: 0 | H34: 0 | I34: 0 | J34: 0 | K34: 0 | L34: 0 | M34: 0 | N34: =SUM(D34:M34) -> 0
A35: Jumlah | C35: =SUM(C9:C34) -> 1570 | D35: 67 | E35: 12 | F35: 33 | G35: 24 | H35: 34 | I35: 32 | J35: 7 | K35: 27 | L35: =SUM(L9:L34) -> 0 | M35: =SUM(M9:M34) -> 0 | N35: =SUM(D35:M35)-G35 -> 212
B36: PERHIT IKU 2A.10 SKS | C36: =(D35+E35+F35+H35+I35+J35+K35+L35+M35)*D36*50/C35 -> 3.3757962 | D36: 0.5
C37: =((N35*D36)/C35)*50 -> 3.3757962 | D37: k(10SKS)
J41: Langsa,
J42: Mengetahui
J45: (…………………………………)
J46: NIP.

Sheet IKU 2A.20SKS
A2: 2A. Mahasiswa Berkegiatan Pembelajaran Di Luar Program Studi Dengan 20 SKS (20 SKS)
A4: No | B4: Program Studi | C4: Jumlah Mahasiswa yang Memenuhi Syarat Menjalankan Kegiatan MBKM | D4: Mahasiswa S1 yang Menghabiskan ≥ 10 SKS di Luar Program Studi | N4: Jumlah
D5: Magang atau praktik kerja | E5: Proyek di Desa | F5: Mengajar di Sekolah | G5: Pertukaran Pelajar | I5: Penelitian atau Riset | J5: Kegiatan Wirausaha | K5: Studi atau proyek Indenpenden | L5: Proyek Kemanusiaan | M5: Bela Negara
G6: Inbound | H6: Outbound
A7: 1 | B7: Hukum | C7: 29 | D7: 11 | E7: - | F7: - | G7: 3 | H7: 10 | I7: 5 | J7: 0 | K7: 0 | L7: 0 | M7: 0 | N7: =SUM(D7:M7) -> 29
A8: 2 | B8: Manajemen | C8: 107 | D8: 9 | E8: - | F8: - | G8: - | H8: - | I8: - | J8: - | K8: - | L8: - | M8: - | N8: =SUM(D8:M8) -> 9
A9: 3 | B9: Ekonomi Pembangunan | C9: 57 | D9: 4 | E9: - | F9: - | G9: - | H9: - | I9: 6 | J9: - | K9: - | L9: - | M9: - | N9: =SUM(D9:M9) -> 10
A10: 4 | B10: Akuntansi | C10: 45 | D10: 1 | E10: - | F10: - | G10: - | H10: - | I10: 7 | J10: - | K10: - | L10: - | M10: - | N10: =SUM(D10:M10) -> 8
A11: 5 | B11: Agroteknologi | C11: 36 | D11: 8 | E11: - | F11: - | G11: - | H11: - | I11: 12 | J11: - | K11: 6 | L11: - | M11: - | N11: =SUM(D11:M11) -> 26
A12: 6 | B12: Agribisnis | C12: 175 | D12: 3 | E12: 5 | F12: - | G12: 12 | H12: 3 | I12: 6 | J12: - | K12: 11 | L12: - | M12: - | N12: =SUM(D12:M12) -> 40
A13: 7 | B13: Akuakultur | C13: 19 | D13: 16 | E13: - | F13: - | G13: - | H13: - | I13: - | J13: - | K13: - | L13: - | M13: - | N13: =SUM(D13:M13) -> 16
A14: 8 | B14: Pendidikan Sejarah | C14: 173 | D14: - | E14: - | F14: - | G14: - | H14: 2 | I14: 5 | J14: - | K14: - | L14: - | M14: - | N14: =SUM(D14:M14) -> 7
A15: 9 | B15: Pendidikan Biologi | C15: 48 | D15: - | E15: - | F15: - | G15: - | H15: - | I15: - | J15: - | K15: - | L15: - | M15: - | N15: =SUM(D15:M15) -> 0
A16: 10 | B16: Pendidikan Bahasa Inggris | C16: 70 | D16: - | E16: - | F16: - | G16: - | H16: - | I16: - | J16: - | K16: - | L16: - | M16: - | N16: =SUM(D16:M16) -> 0
A17: 11 | B17: Pendidikan Bahasa Indonesia | C17: 30 | D17: 10 | E17: - | F17: 10 | G17: - | H17: 10 | I17: - | J17: - | K17: - | L17: - | M17: - | N17: =SUM(D17:M17) -> 30
A18: 12 | B18: Pendidikan Geografi | D18: - | E18: - | F18: - | G18: - | H18: - | I18: - | J18: - | K18: - | L18: - | M18: - | N18: =SUM(D18:M18) -> 0
A19: 13 | B19: Pendidikan Matematika | D19: - | E19: - | F19: - | G19: - | H19: - | I19: - | J19: - | K19: - | L19: - | M19: - | N19: =SUM(D19:M19) -> 0
A20: 14 | B20: Pendidikan Fisika | C20: 68 | D20: - | E20: - | F20: - | G20: - | H20: - | I20: - | J20: - | K20: - | L20: - | M20: - | N20: =SUM(D20:M20) -> 0
A21: 15 | B21: Pendidikan Kimia | C21: 11 | D21: - | E21: - | F21: 5 | G21: - | H21: - | I21: - | J21: - | K21: - | L21: - | M21: - | N21: =SUM(D21:M21) -> 5
A22: 16 | B22: Pendidikan Jasmani | D22: 10 | E22: - | F22: 10 | G22: - | H22: 10 | I22: - | J22: - | K22: - | L22: - | M22: - | N22: =SUM(D22:M22) -> 30
A23: 17 | B23: Pendidikan Guru Sekolah Dasar | C23: 278 | D23: 1 | E23: - | F23: 15 | G23: - | H23: - | I23: - | J23: - | K23: - | L23: - | M23: - | N23: =SUM(D23:M23) -> 16
A24: 18 | B24: Teknik Sipil | C24: 53 | D24: 0 | E24: 0 | F24: 0 | G24: 0 | H24: 0 | I24: 0 | J24: 0 | K24: 0 | L24: 0 | M24: 0 | N24: =SUM(D24:M24) -> 0
A25: 19 | B25: Teknik Mesin | C25: 52 | D25: 0 | E25: 1 | F25: 0 | G25: 0 | H25: 0 | I25: 0 | J25: 0 | K25: 3 | L25: 0 | M25: 0 | N25: =SUM(D25:M25) -> 4
A26: 20 | B26: Teknik Industri | C26: 78 | D26: 10 | E26: 0 | F26: 0 | G26: 0 | H26: 1 | I26: 0 | J26: 0 | K26: 2 | L26: 0 | M26: 0 | N26: =SUM(D26:M26) -> 13
A27: 21 | B27: Informatika | C27: 70 | D27: 0 | E27: 0 | F27: 0 | G27: 0 | H27: 0 | I27: 0 | J27: 0 | K27: 0 | L27: 0 | M27: 0 | N27: =SUM(D27:M27) -> 0
A28: 22 | B28: Matematika | C28: 68 | D28: 6 | E28: 0 | F28: 0 | G28: 0 | H28: 0 | I28: 0 | J28: 0 | K28: 0 | L28: 0 | M28: 0 | N28: =SUM(D28:M28) -> 6
A29: 23 | B29: Fisika | C29: 26 | D29: 4 | E29: 0 | F29: 1 | G29: 0 | H29: 0 | I29: 0 | J29: 0 | K29: 0 | L29: 0 | M29: 0 | N29: =SUM(D29:M29) -> 5
A30: 24 | B30: Biologi | C30: 46 | D30: 6 | E30: 0 | F30: 0 | G30: 3 | H30: 4 | I30: 0 | J30: 0 | K30: 0 | L30: 2 | M30: 0 | N30: =SUM(D30:M30) -> 15
A31: 25 | B31: Kimia | C31: 31 | D31: 1 | E31: 0 | F31: 0 | G31: 0 | H31: 0 | I31: 0 | J31: 0 | K31: 0 | L31: 0 | M31: 0 | N31: =SUM(D31:M31) -> 1
A32: 26 | B32: Geofisika | C32: 0 | D32: 0 | E32: 0 | F32: 0 | G32: 0 | H32: 0 | I32: 0 | J32: 0 | K32: 0 | L32: 0 | M32: 0 | N32: =SUM(D32:M32) -> 0
A33: Jumlah | C33: =SUM(C7:C32) -> 1570 | D33: 145 | E33: 9 | F33: 56 | G33: 37 | H33: 86 | I33: 59 | J33: =SUM(J7:J32) -> 0 | K33: 41 | L33: =SUM(L7:L32) -> 2 | M33: =SUM(M7:M32) -> 0 | N33: =SUM(D33:M33)-G33 -> 398
A34: PERHIT IKU 2A 20 SKS | C34: =(D33+E33+F33+H33+I33+J33+K33+L33+M33)*D34*50/C33 -> 12.675159 | D34: 1
C35: =((N33*D34)/C33)*50 -> 12.675159 | D35: k(20SKS)
J37: Langsa,
J38: Mengetahui
J41: (…………………………………)
J42: NIP.

Sheet IKU INBOUND
A1: 2A. Mahasiswa Berkegiatan Pembelajaran Di Luar Program Studi Dengan 20 SKS (20 SKS)
A3: No | B3: Program Studi | C3: Jumlah Mahasiswa yang Memenuhi Syarat Menjalankan Kegiatan MBKM | D3: Mahasiswa S1 yang Menghabiskan ≥ 10 SKS di Luar Program Studi | N3: Jumlah
D4: Magang atau praktik kerja | E4: Proyek di Desa | F4: Mengajar di Sekolah | G4: Pertukaran Pelajar | I4: Penelitian atau Riset | J4: Kegiatan Wirausaha | K4: Studi atau proyek Indenpenden | L4: Proyek Kemanusiaan | M4: Bela Negara
G5: Inbound | H5: Outbound
A6: 1 | B6: Hukum | C6: 29 | D6: 11 | E6: 0 | F6: 0 | G6: 3 | H6: 10 | I6: 0 | J6: 0 | K6: 0 | L6: 0 | M6: 0 | N6: =SUM(D6:M6) -> 24
A7: 2 | B7: Manajemen | C7: 107 | D7: 9 | E7: 0 | F7: 0 | G7: 4 | H7: 9 | I7: 11 | J7: 0 | K7: 1 | L7: 0 | M7: 0 | N7: =SUM(D7:M7) -> 34
A8: 3 | B8: Ekonomi Pembangunan | C8: 57 | D8: 4 | E8: 0 | F8: 0 | G8: 3 | H8: 5 | I8: 4 | J8: 0 | K8: 0 | L8: 0 | M8: 0 | N8: =SUM(D8:M8) -> 16
A9: 4 | B9: Akuntansi | C9: 45 | D9: 1 | E9: 0 | F9: 0 | G9: 1 | H9: 3 | I9: 7 | J9: 0 | K9: 0 | L9: 0 | M9: 0 | N9: =SUM(D9:M9) -> 12
A10: 5 | B10: Agroteknologi | C10: 36 | D10: 8 | E10: 0 | F10: 0 | G10: 0 | H10: 0 | I10: 12 | J10: 0 | K10: 6 | L10: 0 | M10: 0 | N10: =SUM(D10:M10) -> 26
A11: 6 | B11: Agribisnis | C11: 175 | D11: 3 | E11: 5 | F11: 0 | G11: 12 | H11: 3 | I11: 5 | J11: 2 | K11: 11 | L11: 0 | M11: 0 | N11: =SUM(D11:M11) -> 41
A12: 7 | B12: Akuakultur | C12: 19 | D12: 16 | E12: 0 | F12: 0 | G12: 7 | H12: 5 | I12: 0 | J12: 0 | K12: 0 | L12: 2 | M12: 0 | N12: =SUM(D12:M12) -> 30
A13: 8 | B13: Pendidikan Sejarah | C13: 173 | D13: - | E13: - | F13: - | G13: - | H13: - | I13: - | J13: - | K13: - | L13: - | M13: - | N13: =SUM(D13:M13) -> 0
A14: 9 | B14: Pendidikan Biologi | C14: 48 | D14: - | E14: - | F14: - | G14: - | H14: - | I14: - | J14: - | K14: - | L14: - | M14: - | N14: =SUM(D14:M14) -> 0
A15: 10 | B15: Pendidikan Bahasa Inggris | C15: 70 | D15: - | E15: - | F15: - | G15: - | H15: - | I15: - | J15: - | K15: - | L15: - | M15: - | N15: =SUM(D15:M15) -> 0
A16: 11 | B16: Pendidikan Bahasa Indonesia | C16: 30 | D16: 10 | E16: - | F16: 10 | G16: - | H16: 10 | I16: - | J16: - | K16: - | L16: - | M16: - | N16: =SUM(D16:M16) -> 30
A17: 12 | B17: Pendidikan Geografi | D17: - | E17: - | F17: - | G17: - | H17: - | I17: - | J17: - | K17: - | L17: - | M17: - | N17: =SUM(D17:M17) -> 0
A18: 13 | B18: Pendidikan Matematika | D18: - | E18: - | F18: - | G18: - | H18: - | I18: - | J18: - | K18: - | L18: - | M18: - | N18: =SUM(D18:M18) -> 0
A19: 14 | B19: Pendidikan Fisika | C19: 68 | D19: - | E19: - | F19: - | G19: - | H19: - | I19: - | J19: - | K19: - | L19: - | M19: - | N19: =SUM(D19:M19) -> 0
A20: 15 | B20: Pendidikan Kimia | C20: 11 | D20: - | E20: - | F20: - | G20: - | H20: - | I20: - | J20: - | K20: - | L20: - | M20: - | N20: =SUM(D20:M20) -> 0
A21: 16 | B21: Pendidikan Jasmani | D21: - | E21: - | F21: - | G21: - | H21: - | I21: - | J21: - | K21: - | L21: - | M21: - | N21: =SUM(D21:M21) -> 0
A22: 17 | B22: Pendidikan Guru Sekolah Dasar | C22: 278 | D22: 1 | E22: - | F22: 15 | G22: - | H22: - | I22: - | J22: - | K22: - | L22: - | M22: - | N22: =SUM(D22:M22) -> 16
A23: 18 | B23: Teknik Sipil | C23: 53 | N23: =SUM(D23:M23) -> 0
A24: 19 | B24: Teknik Mesin | C24: 52 | N24: =SUM(D24:M24) -> 0
A25: 20 | B25: Teknik Industri | C25: 78 | N25: =SUM(D25:M25) -> 0
A26: 21 | B26: Informatika | C26: 70 | N26: =SUM(D26:M26) -> 0
A27: 22 | B27: Matematika | C27: 68 | N27: =SUM(D27:M27) -> 0
A28: 23 | B28: Fisika | C28: 26 | N28: =SUM(D28:M28) -> 0
A29: 24 | B29: Biologi | C29: 46 | N29: =SUM(D29:M29) -> 0
A30: 25 | B30: Kimia | C30: 31 | N30: =SUM(D30:M30) -> 0
A31: 26 | B31: Geofisika | C31: 0 | N31: =SUM(D31:M31) -> 0
A32: Jumlah | C32: =SUM(C6:C31) -> 1570 | D32: =SUM(D6:D31) -> 63 | E32: =SUM(E6:E31) -> 5 | F32: =SUM(F6:F31) -> 25 | G32: =SUM(G6:G31) -> 30 | H32: =SUM(H6:H31) -> 45 | I32: =SUM(I6:I31) -> 39 | J32: =SUM(J6:J31) -> 2 | ... N32: =SUM(N6:N31) -> 229
A33: PERHIT IKU 2 INBOUND | C33: =(G36)*D33*20/C32 -> 0.77707006 | D33: 1
D34: k(20SKS) | G34: 24
G35: 37
G36: =SUM(G34:G35) -> 61

Sheet IKU 2B
A5: No | B5: Program Studi | C5: Jumlah Mahasiswa Yang Memenuhi Syarat Menjalankan Kegiatan MBKM | D5: Jumlah Mahasiswa Aktif | H5: Meraih Prestasi Lomba (Juara 1-3) | O5: Prestasi Karya yang Digunakan Dunia Usaha/Industri dan Masyarakat | P5: Sertifikat Kompetensi Internasional | Q5: Jumlah
E6: Internasional | I6: Nasional | L6: Provinsi
E7: I | F7: II | G7: III | H7: Kepesertaan | I7: I | J7: II | K7: III | L7: I | M7: II | N7: III
A8: 1 | B8: Hukum | C8: 29 | D8: 641 | E8: 0 | F8: 0 | G8: 0 | H8: 0 | I8: 0 | J8: 8 | K8: 0 | L8: 0 | M8: 0 | N8: 0 | O8: 0 | P8: 0 | Q8: =SUM(E8:P8) -> 8
A9: 2 | B9: Manajemen | C9: 107 | D9: 617 | E9: 0 | F9: 0 | G9: 0 | H9: 0 | I9: 0 | J9: 0 | K9: 0 | L9: 0 | M9: 1 | N9: 0 | O9: 0 | P9: 0 | Q9: =SUM(E9:P9) -> 1
A10: 3 | B10: Ekonomi Pembangunan | C10: 57 | D10: 269 | E10: 0 | F10: 0 | G10: 0 | H10: 0 | I10: 0 | J10: 0 | K10: 0 | L10: 1 | M10: 1 | N10: 1 | O10: 1 | P10: 0 | Q10: =SUM(E10:P10) -> 4
A11: 4 | B11: Akuntansi | C11: 45 | D11: 365 | E11: 0 | F11: 0 | G11: 1 | H11: 3 | I11: 0 | J11: 0 | K11: 0 | L11: 0 | M11: 0 | N11: 0 | O11: 0 | P11: 0 | Q11: =SUM(E11:P11) -> 4
A12: 5 | B12: Agroteknologi | C12: 36 | D12: 309 | E12: 0 | F12: 0 | G12: 0 | H12: 0 | I12: 0 | J12: 0 | K12: 0 | L12: 0 | M12: 0 | N12: 0 | O12: 0 | P12: 0 | Q12: =SUM(E12:P12) -> 0
A13: 6 | B13: Agribisnis | C13: 175 | D13: 343 | E13: 0 | F13: 0 | G13: 0 | H13: 0 | I13: 0 | J13: 0 | K13: 1 | L13: 0 | M13: 0 | N13: 0 | O13: 0 | P13: 0 | Q13: =SUM(E13:P13) -> 1
A14: 7 | B14: Akuakultur | C14: 19 | D14: 16 | E14: 0 | F14: 0 | G14: 0 | H14: 0 | I14: 0 | J14: 0 | K14: 0 | L14: 0 | M14: 19 | N14: 0 | O14: 0 | P14: 0 | Q14: =SUM(E14:P14) -> 19
A15: 8 | B15: Pendidikan Sejarah | C15: 173 | M15: 3 | N15: 1 | O15: - | P15: - | Q15: =SUM(E15:P15) -> 4
A16: 9 | B16: Pendidikan Biologi | C16: 48 | D16: 260 | E16: - | F16: - | G16: - | H16: - | I16: - | J16: - | K16: - | L16: - | M16: - | N16: - | O16: 2 | P16: - | Q16: =SUM(E16:P16) -> 2
A17: 10 | B17: Pendidikan Bahasa Inggris | C17: 70 | D17: 279 | E17: - | F17: - | G17: - | H17: - | I17: - | J17: - | K17: - | L17: - | M17: - | N17: - | O17: - | P17: - | Q17: =SUM(E17:P17) -> 0
A18: 11 | B18: Pendidikan Bahasa Indonesia | C18: 30 | D18: 317 | E18: - | F18: - | G18: - | H18: - | I18: - | J18: - | K18: - | L18: - | M18: - | N18: - | O18: - | P18: - | Q18: =SUM(E18:P18) -> 0
A19: 12 | B19: Pendidikan Geografi | E19: - | F19: - | G19: - | H19: - | I19: - | J19: - | K19: - | L19: - | M19: - | N19: - | O19: - | P19: - | Q19: =SUM(E19:P19) -> 0
A20: 13 | B20: Pendidikan Matematika | E20: - | F20: - | G20: - | H20: - | I20: - | J20: - | K20: - | L20: - | M20: - | N20: - | O20: - | P20: - | Q20: =SUM(E20:P20) -> 0
A21: 14 | B21: Pendidikan Fisika | C21: 68 | E21: - | F21: - | G21: - | H21: - | I21: - | J21: - | K21: - | L21: - | M21: - | N21: - | O21: - | P21: - | Q21: =SUM(E21:P21) -> 0
A22: 15 | B22: Pendidikan Kimia | C22: 11 | D22: 53 | E22: - | F22: - | G22: - | H22: - | I22: - | J22: - | K22: - | L22: - | M22: - | N22: - | O22: - | P22: - | Q22: =SUM(E22:P22) -> 0
A23: 16 | B23: Pendidikan Jasmani | D23: 417 | E23: - | F23: - | G23: - | H23: - | I23: - | J23: - | K23: - | L23: - | M23: - | N23: - | O23: - | P23: - | Q23: =SUM(E23:P23) -> 0
A24: 17 | B24: Pendidikan Guru Sekolah Dasar | C24: 278 | D24: 520 | E24: - | F24: - | G24: - | H24: - | I24: 1 | J24: - | K24: 3 | L24: - | M24: - | N24: - | O24: 4 | P24: 4 | Q24: =SUM(E24:P24) -> 12
A25: 18 | B25: Teknik Sipil | C25: 53 | D25: 367 | E25: - | F25: - | G25: - | H25: - | I25: - | J25: - | K25: - | L25: - | M25: - | N25: - | O25: - | P25: - | Q25: =SUM(E25:P25) -> 0
A26: 19 | B26: Teknik Mesin | C26: 52 | D26: 279 | E26: - | F26: - | G26: - | H26: - | I26: - | J26: - | K26: - | L26: - | M26: - | N26: - | O26: - | P26: - | Q26: =SUM(E26:P26) -> 0
A27: 20 | B27: Teknik Industri | C27: 78 | D27: 261 | E27: 0 | F27: 0 | G27: 0 | H27: 0 | I27: 0 | J27: 0 | K27: 0 | L27: 0 | M27: 0 | N27: 0 | O27: 0 | P27: 0 | Q27: =SUM(E27:P27) -> 0
A28: 21 | B28: Informatika | C28: 70 | D28: 509 | E28: 0 | F28: 0 | G28: 0 | H28: 0 | I28: 0 | J28: 0 | K28: 0 | L28: 0 | M28: 0 | N28: 0 | O28: 0 | P28: 0 | Q28: =SUM(E28:P28) -> 0
A29: 22 | B29: Matematika | C29: 68 | D29: 68 | E29: 0 | F29: 0 | G29: 0 | H29: 0 | I29: 0 | J29: 0 | K29: 0 | L29: 0 | M29: 0 | N29: 0 | O29: 2 | P29: 0 | Q29: =SUM(E29:P29) -> 2
A30: 23 | B30: Fisika | C30: 26 | D30: 35 | E30: 0 | F30: 0 | G30: 0 | H30: 0 | I30: 0 | J30: 0 | K30: 0 | L30: 0 | M30: 0 | N30: 0 | O30: 0 | P30: 0 | Q30: =SUM(E30:P30) -> 0
A31: 24 | B31: Biologi | C31: 46 | D31: 70 | E31: 0 | F31: 0 | G31: 0 | H31: 1 | I31: 0 | J31: 0 | K31: 0 | L31: 1 | M31: 1 | N31: 1 | O31: 0 | P31: 0 | Q31: =SUM(E31:P31) -> 4
A32: 25 | B32: Kimia | C32: 31 | D32: 48 | E32: 0 | F32: 0 | G32: 0 | H32: 0 | I32: 0 | J32: 0 | K32: 0 | L32: 0 | M32: 0 | N32: 0 | O32: 0 | P32: 0 | Q32: =SUM(E32:P32) -> 0
A33: 26 | B33: Geofisika | C33: 0 | D33: 5 | E33: 0 | F33: 0 | G33: 0 | H33: 0 | I33: 0 | J33: 0 | K33: 0 | L33: 0 | M33: 0 | N33: 0 | O33: 0 | P33: 0 | Q33: =SUM(E33:P33) -> 0
A34: Jumlah | C34: =SUM(C8:C33) -> 1570 | D34: 7493 | E34: =SUM(E8:E33) -> 0 | F34: =SUM(F8:F33) -> 0 | G34: =SUM(G8:G33) -> 1 | H34: =SUM(H8:H33) -> 4 | I34: =SUM(I8:I33) -> 1 | J34: =SUM(J8:J33) -> 8 | K34: =SUM(K8:K33) -> 4 | L34: =SUM(L8:L33) -> 2 | M34: 27 | N34: =SUM(N8:N33) -> 3 | O34: =SUM(O8:O33) -> 9 | P34: =SUM(P8:P33) -> 4 | Q34: =SUM(Q8:Q33) -> 61
B35: PERHIT IKU 2C | C35: =Q37 -> 0.082476979 | E35: 1 | F35: 0.9 | G35: 0.8 | H35: 0.7 | I35: 0.7 | J35: 0.6 | K35: 0.5 | L35: 0.4 | M35: 0.3 | N35: 0.2 | O35: sigma c*k | P35: sigma c*k | Q35: sigma c*k | R35: x 30
E36: k1 | F36: k2 | G36: k3 | H36: k4 | I36: k5 | J36: k6 | K36: k7 | L36: k8 | M36: k9 | N36: k10 | P36: y | Q36: y
D37: c*k | E37: =E34*E35 -> 0 | F37: =F34*F35 -> 0 | G37: =G34*G35 -> 0.8 | H37: =H34*H35 -> 2.8 | I37: =I34*I35 -> 0.7 | J37: =J34*J35 -> 4.8 | K37: =K34*K35 -> 2 | L37: =L34*L35 -> 0.8 | ... N37: =N34*N35 -> 0.6 | O37: =SUM(E37:N37) -> 20.6 | P37: =O37/D34 -> 0.0027492326 | Q37: =P37*30 -> 0.082476979
E38: 0 | F38: 0 | G38: 1 | H38: 7 | I38: 2 | J38: 14 | K38: 1 | L38: 2 | M38: 27 | N38: 2
O41: Langsa,
O42: Mengetahui
O45: (…………………………………)
O46: NIP.
B50: Jenis Hitungan | C50: Jenis Bobot | F50: Hasil Hitung
C51: Internasional | D51: Nasional | E51: Provinsi | I51: nasional | M51: provinsi
...

Sheet PERHIT IKU 2
A7: Target | B7: 20
A8: TARGET IKU 2 | B8: 20 | C8: CAPAIAN
A9: REALISASI
A10: PEMBELAJARAN DI LUAR PRODI | B10: ='PERHIT IKU 2A.10SKS'!C36+'IKU 2A.20SKS'!C34 -> 16.050955 | C10: =B13/B8*100 -> 84.552512
A11: MAHASISWA INBOUND | B11: ='IKU INBOUND'!C33 -> 0.77707006
A12: MAHASISWA BERPRESTASI | B12: ='IKU 2B'!Q37 -> 0.082476979
A13: TOTAL | B13: =SUM(B10:B12) -> 16.910502

Sheet IKU 3A
A1: FAKULTAS : | I1: IKU 3C
A9: No | B9: Program Studi | C9: Total Dosen NIDN/NIDK | D9: Surat Persetujuan PT Asal | E9: Kegiatan Tridarma dan Persyaratan | K9: Jumlah
E10: Kategori Kegiatan | H10: Surat Kontrak Kerja | I10: Perguruan Tinggi
E11: Pendidikan | F11: Penelitian | G11: Pengabdian | I11: Negeri | J11: Swasta
A12: 1 | B12: Hukum | C12: 17 | D12: 0 | E12: 0 | F12: 0 | G12: 0 | H12: 3 | I12: 7 | K12: =SUM(E12:J12) -> 10
A13: 2 | B13: Manajemen | C13: 24 | D13: 0 | E13: 5 | F13: 3 | G13: 13 | H13: 4 | I13: 2 | J13: 0
A14: 3 | B14: Ekonomi Pembangunan | C14: 15 | D14: 0 | E14: 0 | F14: 16 | G14: 8 | H14: 24 | I14: 24 | J14: 0
A15: 4 | B15: Akuntansi | C15: 10 | D15: 0 | E15: 3 | F15: 1 | G15: 8 | H15: 12 | I15: 12 | J15: 0
A16: 5 | B16: Agroteknologi | C16: 15 | D16: 0 | E16: 0 | F16: 0 | G16: 0 | H16: 0 | I16: 0 | J16: 0
A17: 6 | B17: Agribisnis | C17: 13 | D17: 0 | E17: 0 | F17: 0 | G17: 0 | H17: 0 | I17: 0 | J17: 0
A18: 7 | B18: Akuakultur | C18: 8 | D18: 1 | E18: 0 | F18: 0 | G18: 1 | H18: 1 | I18: 0 | J18: 1
A19: 8 | B19: Pendidikan Sejarah | C19: 3 | D19: 3 | E19: 3 | F19: 5 | G19: 1 | H19: 8 | I19: - | J19: -
A20: 9 | B20: Pendidikan Biologi | C20: 23 | D20: 1 | E20: 1 | F20: 4 | G20: 1 | H20: - | I20: 5 | J20: 1
A21: 10 | B21: Pendidikan Bahasa Inggris | C21: 22 | D21: 3 | E21: 10 | F21: 8 | G21: 21 | H21: - | I21: - | J21: -
A22: 11 | B22: Pendidikan Bahasa Indonesia | C22: 11 | D22: - | E22: 11 | F22: 4 | G22: 5 | H22: - | I22: - | J22: -
A23: 12 | B23: Pendidikan Geografi | D23: - | E23: - | F23: - | G23: - | H23: - | I23: - | J23: -
A24: 13 | B24: Pendidikan Matematika | D24: - | E24: - | F24: - | G24: - | H24: - | I24: - | J24: -
A25: 14 | B25: Pendidikan Fisika | C25: 8 | D25: - | E25: - | F25: - | G25: - | H25: - | I25: - | J25: -
A26: 15 | B26: Pendidikan Kimia | C26: 10 | D26: - | E26: - | F26: - | G26: - | H26: - | I26: - | J26: -
A27: 16 | B27: Pendidikan Jasmani | C27: 17 | D27: - | E27: 17 | F27: 4 | G27: 3 | H27: - | I27: - | J27: -
A28: 17 | B28: Pendidikan Guru Sekolah Dasar | D28: - | E28: - | F28: - | G28: - | H28: - | I28: - | J28: -
A29: 18 | B29: Teknik Sipil | C29: 23 | D29: 23 | E29: 0 | F29: 0 | G29: 0 | H29: 0 | I29: 0 | J29: 0
A30: 19 | B30: Teknik Mesin | C30: 16 | D30: 16 | E30: 0 | F30: 0 | G30: 0 | H30: 0 | I30: 0 | J30: 0
A31: 20 | B31: Teknik Industri | C31: 9 | D31: 9 | E31: 0 | F31: 0 | G31: 0 | H31: 1 | I31: 0 | J31: 1
A32: 21 | B32: Informatika | C32: 13 | D32: 13 | E32: 0 | F32: 0 | G32: 0 | H32: 0 | I32: 0 | J32: 0
A33: 22 | B33: Matematika | C33: 7 | D33: 7 | E33: 0 | F33: 0 | G33: 0 | H33: 0 | I33: 0 | J33: 0
A34: 23 | B34: Fisika | C34: 6 | D34: 6 | E34: 0 | F34: 0 | G34: 1 | H34: 0 | I34: 0 | J34: 0
A35: 24 | B35: Biologi | C35: 14 | D35: 2 | E35: 1 | F35: 2 | G35: 0 | H35: 0 | I35: 2 | J35: 1
A36: 25 | B36: Kimia | C36: 8 | D36: 8 | E36: 0 | F36: 0 | G36: 0 | H36: 0 | I36: 0 | J36: 0 | K36: =SUM(E36:J36) -> 0
A37: 26 | B37: Geofisika | C37: 6 | D37: 6 | E37: 0 | F37: 0 | G37: 2 | H37: 0 | I37: 2 | J37: 2 | K37: =SUM(E37:J37) -> 6
A38: Jumlah | C38: 486 | D38: =SUM(D12:D37) -> 98 | E38: =SUM(E12:E37) -> 51 | F38: =SUM(F12:F37) -> 47 | G38: =SUM(G12:G37) -> 64 | I38: =SUM(I12:I37) -> 54 | J38: =SUM(J12:J37) -> 6 | K38: =SUM(K12:K37) -> 16
B39: PERHIT IKU 3A | C39: =F39/C38*100 -> 33.333333 | D39: 1 | E39: =SUM(E38:G38) -> 162 | F39: =E39*D39 -> 162
D40: k | E40: n*k | F40: Ʃn*k
B41: Kriteria | D41: Bobot | E41: Hasil
B42: Tridharma (di PT Lain) | D42: 1 | E42: =E39*D42*100/C38 -> 33.333333 | G42: =E39*D42 -> 162
G43: =G42/C38 -> 0.33333333
G44: =G43*100 -> 33.333333
H49: Langsa,
H50: Mengetahui
H53: (…………………………………)
...

Sheet IKU 3B
A2: 3B. Dosen Yang Bekerja Sebagai Praktisi (dalam 5 tahun terakhir)
A4: NO. | B4: PRODI | C4: JUMLAH DOSEN MENJADI PENELITI, KONSULTAN, ASESOR, PEGAWAI PENUH WAKTU (FULL TIME), ATAU PARUH WAKTU (PART TIME) | D4: JUMLAH DOSEN MENJADI WIRASWASTA PENDIRI (FOUNDER)ATAU PASANGAN PENDIRI (CO-FOUNDER) | E4: JUMLAH DOSEN KHUSUS UNTUK DOSEN DARI PROGRAM STUDI SENI BUDAYA DAPAT JUGA BERKEGIATAN LAINNYA SESUAI KEPMEN | F4: Jumlah
A5: 1 | B5: Hukum | C5: 6 | D5: 0 | E5: 0 | F5: =SUM(C5:E5) -> 6
A6: 2 | B6: Manajemen | C6: 1 | D6: 1 | E6: 0 | F6: =SUM(C6:E6) -> 2
A7: 3 | B7: Ekonomi Pembangunan | C7: 4 | D7: 0 | E7: 0 | F7: =SUM(C7:E7) -> 4
A8: 4 | B8: Akuntansi | C8: 1 | D8: 1 | E8: 0 | F8: =SUM(C8:E8) -> 2
A9: 5 | B9: Agroteknologi | C9: 0 | D9: 0 | E9: 0 | F9: =SUM(C9:E9) -> 0
A10: 6 | B10: Agribisnis | C10: 13 | D10: 4 | E10: 0 | F10: =SUM(C10:E10) -> 17
A11: 7 | B11: Budidaya Perairan | C11: 2 | D11: 3 | E11: 0 | F11: =SUM(C11:E11) -> 5
A12: 8 | B12: Pendidikan Sejarah | C12: 5 | D12: - | E12: - | F12: =SUM(C12:E12) -> 5
A13: 9 | B13: Pendidikan Biologi | C13: 2 | D13: 4 | E13: - | F13: =SUM(C13:E13) -> 6
A14: 10 | B14: Pendidikan Bahasa Inggris | C14: 2 | D14: - | E14: - | F14: =SUM(C14:E14) -> 2
A15: 11 | B15: Pendidikan Bahasa Indonesia | C15: 1 | D15: - | E15: - | F15: =SUM(C15:E15) -> 1
A16: 12 | B16: Pendidikan Geografi | C16: - | D16: - | E16: - | F16: =SUM(C16:E16) -> 0
A17: 13 | B17: Pendidikan Matematika | C17: - | D17: - | E17: - | F17: =SUM(C17:E17) -> 0
A18: 14 | B18: Pendidikan Fisika | C18: 2 | D18: 2 | E18: - | F18: =SUM(C18:E18) -> 4
A19: 15 | B19: Pendidikan Kimia | C19: - | D19: - | E19: - | F19: =SUM(C19:E19) -> 0
A20: 16 | B20: Pendidikan Jasmani | C20: 1 | D20: - | E20: - | F20: =SUM(C20:E20) -> 1
A21: 17 | B21: Pendidikan Guru Sekolah Dasar | C21: 2 | D21: 2 | E21: - | F21: =SUM(C21:E21) -> 4
A22: 18 | B22: Teknik Sipil | C22: 0 | D22: 8 | E22: 0 | F22: =SUM(C22:E22) -> 8
A23: 19 | B23: Teknik Mesin | C23: 0 | D23: 0 | E23: 0 | F23: =SUM(C23:E23) -> 0
